<robot name="micro4.0">

  <!-- 1. 添加虚拟根节点 (防止 KDL 报错和物理引擎崩溃) -->
  <link name="base_footprint"/>

  <joint name="base_joint" type="fixed">
    <parent link="base_footprint"/>
    <child link="base_link"/>
    <origin xyz="0 0 0" rpy="0 0 0"/>
  </joint>

  <link name="base_link">
    <inertial>
      <origin xyz="-0.0038 0 -0.0066" rpy="0 0 0" />
      <mass value="0.22" />
      <inertia ixx="0.00016" ixy="0" ixz="0" iyy="0.00017" iyz="0" izz="0.00030" />
    </inertial>
    <visual>
      <origin xyz="0 0 0" rpy="0 0 0" />
      <geometry>
        <mesh filename="package://yahboomcar_description/meshes/base_link.STL" />
      </geometry>
      <material name="white"><color rgba="1 1 1 1" /></material>
    </visual>
    <collision>
      <origin xyz="0 0 0" rpy="0 0 0" />
      <geometry>
        <mesh filename="package://yahboomcar_description/meshes/base_link.STL" />
      </geometry>
    </collision>
  </link>

  <!-- 2. 四个轮子 (这里保留你的原始数据，但简化一下以防万一) -->
  <!-- 左前轮 -->
  <link name="zq_Link">
    <inertial>
      <origin xyz="0 0 0" rpy="0 0 0" />
      <mass value="0.2" />
      <inertia ixx="0.000002" ixy="0" ixz="0" iyy="0.000004" iyz="0" izz="0.000002" />
    </inertial>
    <visual>
      <geometry><mesh filename="package://yahboomcar_description/meshes/zq_Link.STL" /></geometry>
    </visual>
    <collision>
      <geometry><mesh filename="package://yahboomcar_description/meshes/zq_Link.STL" /></geometry>
    </collision>
  </link>
  <joint name="zq_Joint" type="continuous">
    <origin xyz="0.0455 0.0675 -0.02125" rpy="0 0 0" />
    <parent link="base_link" />
    <child link="zq_Link" />
    <axis xyz="0 1 0" />
  </joint>

  <!-- 右前轮 -->
  <link name="yq_Link">
    <inertial>
      <origin xyz="0 0 0" rpy="0 0 0" />
      <mass value="0.2" />
      <inertia ixx="0.000002" ixy="0" ixz="0" iyy="0.000004" iyz="0" izz="0.000002" />
    </inertial>
    <visual>
      <geometry><mesh filename="package://yahboomcar_description/meshes/yq_Link.STL" /></geometry>
    </visual>
    <collision>
      <geometry><mesh filename="package://yahboomcar_description/meshes/yq_Link.STL" /></geometry>
    </collision>
  </link>
  <joint name="yq_Joint" type="continuous">
    <origin xyz="0.0455 -0.0675 -0.02125" rpy="0 0 0" />
    <parent link="base_link" />
    <child link="yq_Link" />
    <axis xyz="0 1 0" /> <!-- 注意：这里你的原始代码写的是 -1，通常我们统一用 1 然后靠插件反转 -->
  </joint>

  <!-- 左后轮 -->
  <link name="zh_Link">
    <inertial>
      <origin xyz="0 0 0" rpy="0 0 0" />
      <mass value="0.2" />
      <inertia ixx="0.000002" ixy="0" ixz="0" iyy="0.000004" iyz="0" izz="0.000002" />
    </inertial>
    <visual>
      <geometry><mesh filename="package://yahboomcar_description/meshes/zh_Link.STL" /></geometry>
    </visual>
    <collision>
      <geometry><mesh filename="package://yahboomcar_description/meshes/zh_Link.STL" /></geometry>
    </collision>
  </link>
  <joint name="zh_Joint" type="continuous">
    <origin xyz="-0.0495 0.0675 -0.02125" rpy="0 0 0" />
    <parent link="base_link" />
    <child link="zh_Link" />
    <axis xyz="0 1 0" />
  </joint>

  <!-- 右后轮 -->
  <link name="yh_Link">
    <inertial>
      <origin xyz="0 0 0" rpy="0 0 0" />
      <mass value="0.2" />
      <inertia ixx="0.000002" ixy="0" ixz="0" iyy="0.000004" iyz="0" izz="0.000002" />
    </inertial>
    <visual>
      <geometry><mesh filename="package://yahboomcar_description/meshes/yh_Link.STL" /></geometry>
    </visual>
    <collision>
      <geometry><mesh filename="package://yahboomcar_description/meshes/yh_Link.STL" /></geometry>
    </collision>
  </link>
  <joint name="yh_Joint" type="continuous">
    <origin xyz="-0.0495 -0.0675 -0.02125" rpy="0 0 0" />
    <parent link="base_link" />
    <child link="yh_Link" />
    <axis xyz="0 1 0" /> <!-- 修正为 1 -->
  </joint>

  <!-- IMU (保留) -->
  <link name="imu_Link">
    <inertial>
      <origin xyz="0 0 0" rpy="0 0 0" />
      <mass value="0.01" />
      <inertia ixx="0.00001" ixy="0" ixz="0" iyy="0.00001" iyz="0" izz="0.00001" />
    </inertial>
    <visual>
      <geometry><mesh filename="package://yahboomcar_description/meshes/imu_Link.STL" /></geometry>
    </visual>
  </link>
  <joint name="imu_Joint" type="fixed">
    <origin xyz="-0.0029 -0.003 0.0317" rpy="0 0 0" />
    <parent link="base_link" />
    <child link="imu_Link" />
  </joint>

  <!-- 3. 激光雷达 (重点修复：添加 Gazebo 传感器定义) -->
  <link name="radar_Link">
    <inertial>
      <origin xyz="0 0 0" rpy="0 0 0" />
      <mass value="0.038" />
      <inertia ixx="0.00001" ixy="0" ixz="0" iyy="0.00001" iyz="0" izz="0.00002" />
    </inertial>
    <visual>
      <geometry><mesh filename="package://yahboomcar_description/meshes/radar_Link.STL" /></geometry>
    </visual>
    <collision>
      <geometry><mesh filename="package://yahboomcar_description/meshes/radar_Link.STL" /></geometry>
    </collision>
  </link>
  <joint name="radar_Joint" type="fixed">
    <origin xyz="0 0 0.0789" rpy="0 0 0" />
    <parent link="base_link" />
    <child link="radar_Link" />
  </joint>


  <!-- 机械臂部分 (保留但不改动) -->
  <link name="jq1_Link">
    <visual><geometry><mesh filename="package://yahboomcar_description/meshes/jq1_Link.STL" /></geometry></visual>
    <inertial><mass value="0.01"/><inertia ixx="0.001" ixy="0" ixz="0" iyy="0.001" iyz="0" izz="0.001"/></inertial>
  </link>
  <joint name="jq1_Joint" type="fixed">
    <origin xyz="0.064 0 0.014" rpy="0 0 0" />
    <parent link="base_link" />
    <child link="jq1_Link" />
  </joint>
  <link name="jq2_Link">
    <visual><geometry><mesh filename="package://yahboomcar_description/meshes/jq2_Link.STL" /></geometry></visual>
    <inertial><mass value="0.01"/><inertia ixx="0.001" ixy="0" ixz="0" iyy="0.001" iyz="0" izz="0.001"/></inertial>
  </link>
  <joint name="jq2_Joint" type="fixed">
    <origin xyz="0.016 0 0.023" rpy="0 0 0" />
    <parent link="jq1_Link" />
    <child link="jq2_Link" />
  </joint>

  <!-- 4. ⚠️ 差速驱动插件 (让车动起来) -->
  <gazebo>
    <plugin name='diff_drive' filename='libgazebo_ros_diff_drive.so'>
      <ros>
        <namespace>/</namespace>
        <remapping>cmd_vel:=cmd_vel</remapping>
        <remapping>odom:=odom</remapping>
      </ros>
      <update_rate>30</update_rate>
      <!-- 轮子配置 (假设是四轮驱动，这里用两轮差速模拟) -->
      <left_joint>zq_Joint</left_joint>
      <right_joint>yq_Joint</right_joint>
      <wheel_separation>0.135</wheel_separation>
      <wheel_diameter>0.065</wheel_diameter>
      <max_wheel_torque>20</max_wheel_torque>
      <max_wheel_acceleration>1.0</max_wheel_acceleration>
      <publish_odom>true</publish_odom>
      <publish_odom_tf>true</publish_odom_tf>
      <publish_wheel_tf>false</publish_wheel_tf>
      <odometry_frame>odom</odometry_frame>
      <robot_base_frame>base_footprint</robot_base_frame>
    </plugin>
  </gazebo>

</robot>
